Workbook

Sheet Export Worksheet
A1: MIDAS_NO | B1: BATCH_ID | C1: BATCH_NAME | D1: CREATED | E1: COMPLETED | F1: NUM_DATA_RECORDS_LOADED | G1: NUM_DATA_RECORDS_VALID | H1: NUM_DATA_RECORDS_ERRORED | I1: NUM_DATA_RECORDS_SKIPPED | J1: CREATED_BY | K1: MIDAS_NO | L1: STATUS | M1: On Tableau
A2: 010928M | B2: 34950 | C2: 603026 oct | D2: 13-10-2025 | E2: 13-10-2025 | F2: 1 | G2: 1 | H2: 0 | I2: 0 | J2: C192 | K2: 010928M | L2: COMPLETED | M2: =VLOOKUP(A2,'Tableau single and bulk'!A:B,2,FALSE) -> NEBAUTO
A3: 010931M | B3: 34937 | C3: Sept 2025 NEs | D3: 13-10-2025 | E3: 13-10-2025 | F3: 27 | G3: 27 | H3: 0 | I3: 0 | J3: Y337 | K3: 010931M | L3: COMPLETED | M3: =VLOOKUP(A3,'Tableau single and bulk'!A:B,2,FALSE) -> NEBAUTO
A4: 010991M | B4: 34916 | C4: Belvedere College | D4: 10-10-2025 | E4: 10-10-2025 | F4: 1 | G4: 1 | H4: 0 | I4: 0 | J4: X967 | K4: 010991M | L4: COMPLETED | M4: =VLOOKUP(A4,'Tableau single and bulk'!A:B,2,FALSE) -> NEBAUTO
A5: 010996M | B5: 34949 | C5: Sept 2025 NEs | D5: 13-10-2025 | E5: 13-10-2025 | F5: 66 | G5: 66 | H5: 0 | I5: 0 | J5: Y337 | K5: 010996M | L5: COMPLETED | M5: =VLOOKUP(A5,'Tableau single and bulk'!A:B,2,FALSE) -> NEBAUTO
A6: 010998M | B6: 34935 | C6: 2 Sept 2025 NEs | D6: 13-10-2025 | E6: 13-10-2025 | F6: 2 | G6: 2 | H6: 0 | I6: 0 | J6: Y337 | K6: 010998M | L6: COMPLETED | M6: =VLOOKUP(A6,'Tableau single and bulk'!A:B,2,FALSE) -> NEBAUTO
A7: 011007M | B7: 34940 | C7: Sept 2025 NEs | D7: 13-10-2025 | E7: 13-10-2025 | F7: 50 | G7: 50 | H7: 0 | I7: 0 | J7: Y337 | K7: 011007M | L7: COMPLETED | M7: =VLOOKUP(A7,'Tableau single and bulk'!A:B,2,FALSE) -> NEBAUTO
A8: 011040M | B8: 34943 | C8: 603616 1ne | D8: 13-10-2025 | E8: 13-10-2025 | F8: 1 | G8: 1 | H8: 0 | I8: 0 | J8: F243 | K8: 011040M | L8: COMPLETED | M8: =VLOOKUP(A8,'Tableau single and bulk'!A:B,2,FALSE) -> NEBAUTO
A9: 011045M | B9: 34843 | C9: Petrogas | D9: 08-10-2025 | E9: 08-10-2025 | F9: 1 | G9: 1 | H9: 0 | I9: 0 | J9: X967 | K9: 011045M | L9: COMPLETED | M9: =VLOOKUP(A9,'Tableau single and bulk'!A:B,2,FALSE) -> NEBAUTO
A10: 011053M | B10: 34846 | C10: Petrogas | D10: 08-10-2025 | E10: 08-10-2025 | F10: 1 | G10: 1 | H10: 0 | I10: 0 | J10: X967 | K10: 011053M | L10: COMPLETED | M10: =VLOOKUP(A10,'Tableau single and bulk'!A:B,2,FALSE) -> NEBAUTO
A11: 011054M | B11: 34909 | C11: 609862 | D11: 10-10-2025 | E11: 10-10-2025 | F11: 29 | G11: 29 | H11: 0 | I11: 0 | J11: J987 | K11: 011054M | L11: COMPLETED | M11: =VLOOKUP(A11,'Tableau single and bulk'!A:B,2,FALSE) -> NEBAUTO
A12: 011072M | B12: 34920 | C12: Cupa Operations | D12: 10-10-2025 | E12: 10-10-2025 | F12: 1 | G12: 1 | H12: 0 | I12: 0 | J12: X967 | K12: 011072M | L12: COMPLETED | M12: =VLOOKUP(A12,'Tableau single and bulk'!A:B,2,FALSE) -> NEBAUTO
A13: 011093M | B13: 34850 | C13: Capventis | D13: 08-10-2025 | E13: 08-10-2025 | F13: 1 | G13: 1 | H13: 0 | I13: 0 | J13: X967 | K13: 011093M | L13: COMPLETED | M13: =VLOOKUP(A13,'Tableau single and bulk'!A:B,2,FALSE) -> NEBAUTO
... A37: 011621M | B37: 34998 | C37: 2944 10 | D37: 14-10-2025 | E37: 14-10-2025 | F37: 1 | G37: 1 | H37: 0 | I37: 0 | J37: C192 | K37: 011621M | L37: COMPLETED | M37: =VLOOKUP(A37,'Tableau single and bulk'!A:B,2,FALSE) -> NEBAUTO
A38: 011637M | B38: 34934 | C38: 603782 48ne | D38: 13-10-2025 | E38: 13-10-2025 | F38: 48 | G38: 48 | H38: 0 | I38: 0 | J38: F243 | K38: 011637M | L38: COMPLETED | M38: =VLOOKUP(A38,'Tableau single and bulk'!A:B,2,FALSE) -> #N/A | N38: Archived
A39: 011697M | B39: 34973 | C39: 606901 1NE | D39: 14-10-2025 | E39: 14-10-2025 | F39: 1 | G39: 1 | H39: 0 | I39: 0 | J39: F243 | K39: 011697M | L39: COMPLETED | M39: =VLOOKUP(A39,'Tableau single and bulk'!A:B,2,FALSE) -> NEBAUTO
A40: 011703M | B40: 34997 | C40: 602254 | D40: 14-10-2025 | E40: 14-10-2025 | F40: 13 | G40: 13 | H40: -12 | I40: 12 | J40: J905 | K40: 011703M | L40: COMPLETED | M40: =VLOOKUP(A40,'Tableau single and bulk'!A:B,2,FALSE) -> NEBAUTO
A41: 011722M | B41: 35006 | C41: Opening HR Limited | D41: 14-10-2025 | E41: 14-10-2025 | F41: 1 | G41: 1 | H41: 0 | I41: 0 | J41: X967 | K41: 011722M | L41: COMPLETED | M41: =VLOOKUP(A41,'Tableau single and bulk'!A:B,2,FALSE) -> NEBAUTO
A42: 011920M | B42: 34968 | C42: Eimear Doyle | D42: 14-10-2025 | E42: 14-10-2025 | F42: 1 | G42: 1 | H42: 0 | I42: 0 | J42: Y337 | K42: 011920M | L42: COMPLETED | M42: =VLOOKUP(A42,'Tableau single and bulk'!A:B,2,FALSE) -> NEBAUTO
A43: 011928M | B43: 35023 | C43: Oct 2025 NEs | D43: 15-10-2025 | E43: 15-10-2025 | F43: 31 | G43: 31 | H43: 0 | I43: 0 | J43: Y337 | K43: 011928M | L43: COMPLETED | M43: =VLOOKUP(A43,'Tableau single and bulk'!A:B,2,FALSE) -> NEBAUTO
A44: 011943M | B44: 35012 | C44: Gowan Group Ltd | D44: 15-10-2025 | E44: 15-10-2025 | F44: 3 | G44: 3 | H44: -1 | I44: 1 | J44: X967 | K44: 011943M | L44: COMPLETED | M44: =VLOOKUP(A44,'Tableau single and bulk'!A:B,2,FALSE) -> NEBAUTO
A45: 011946M | B45: 35019 | C45: 606866 Ne Bulk | D45: 15-10-2025 | E45: 15-10-2025 | F45: 4 | G45: 4 | H45: 0 | I45: 0 | J45: J905 | K45: 011946M | L45: COMPLETED | M45: =VLOOKUP(A45,'Tableau single and bulk'!A:B,2,FALSE) -> NEBAUTO
A46: 011956M | B46: 34911 | C46: Agri Health | D46: 10-10-2025 | E46: 10-10-2025 | F46: 3 | G46: 3 | H46: 0 | I46: 0 | J46: X967 | K46: 011956M | L46: COMPLETED | M46: =VLOOKUP(A46,'Tableau single and bulk'!A:B,2,FALSE) -> NEBAUTO
A47: 011958M | B47: 35032 | C47: x27 NEs 15102025 | D47: 15-10-2025 | E47: 15-10-2025 | F47: 27 | G47: 27 | H47: -1 | I47: 1 | J47: H506 | K47: 011958M | L47: COMPLETED | M47: =VLOOKUP(A47,'Tableau single and bulk'!A:B,2,FALSE) -> NEBAUTO
A48: 011972M | B48: 35020 | C48: Magnet Networks | D48: 15-10-2025 | E48: 15-10-2025 | F48: 1 | G48: 1 | H48: 0 | I48: 0 | J48: X967 | K48: 011972M | L48: COMPLETED | M48: =VLOOKUP(A48,'Tableau single and bulk'!A:B,2,FALSE) -> NEBAUTO
A49: 011988M | B49: 35039 | C49: 606840 oct | D49: 15-10-2025 | E49: 15-10-2025 | F49: 7 | G49: 7 | H49: -3 | I49: 3 | J49: C192 | K49: 011988M | L49: COMPLETED | M49: =VLOOKUP(A49,'Tableau single and bulk'!A:B,2,FALSE) -> NEBAUTO
A50: 011991M | B50: 34970 | C50: Laura Farrell | D50: 14-10-2025 | E50: 14-10-2025 | F50: 1 | G50: 1 | H50: 0 | I50: 0 | J50: Y337 | K50: 011991M | L50: COMPLETED | M50: =VLOOKUP(A50,'Tableau single and bulk'!A:B,2,FALSE) -> NEBAUTO
... A642: O423996 | B642: 35559 | C642: 602334 Firhouse | D642: 29-10-2025 | E642: 29-10-2025 | F642: 3 | G642: 3 | H642: 0 | I642: 0 | J642: F243 | K642: O423996 | L642: COMPLETED | M642: =VLOOKUP(A642,'Tableau single and bulk'!A:B,2,FALSE) -> #N/A
A643: O424006 | B643: 35560 | C643: 602334 Hermitage | D643: 29-10-2025 | E643: 29-10-2025 | F643: 7 | G643: 7 | H643: 0 | I643: 0 | J643: F243 | K643: O424006 | L643: COMPLETED | M643: =VLOOKUP(A643,'Tableau single and bulk'!A:B,2,FALSE) -> #N/A | N643: completed in Nov
A644: O426025 | B644: 35581 | C644: Bord na Mona | D644: 30-10-2025 | E644: 30-10-2025 | F644: 3 | G644: 3 | H644: 0 | I644: 0 | J644: X967 | K644: O426025 | L644: COMPLETED | M644: =VLOOKUP(A644,'Tableau single and bulk'!A:B,2,FALSE) -> NEBAUTO

Sheet Sheet2
A3: Row Labels | B3: Count of Bulk Numbers Loaded
B4: 1
A5: NEBAUTO | B5: 294
A6: NESAUTO | B6: 224
A7: #N/A | B7: 8
A8: (blank)
A9: Grand Total | B9: 527

Sheet IP_Org_Usecase_Submission_Statu
A1: MIDAS_NO | B1: Organization Name | C1: Use Case Name | D1: Submission Date and Time (UTC) | E1: Reference Number | F1: Submission Status | G1: Organization Status | H1: Bulk Numbers Loaded | I1: Bulk or Single WI | J1: Comments | K1: Completed | L1: Scheme Number | M1: Scheme Name
A2: 010921M | B2: eircom | C2: Add Members | D2: 2025-10-13 13:14:11.903000Z | E2: 010921M | F2: Completed | G2: Active | H2: =VLOOKUP(A2,'Export Worksheet'!A:L,6,FALSE) -> #N/A | I2: =VLOOKUP(A2,'Tableau single and bulk'!A:B,2,FALSE) -> NESAUTO | K2: =VLOOKUP(A2,'Tableau single and bulk'!A:I,9,FALSE) -> 45943.593 | L2: =VLOOKUP(A2,'Tableau single and bulk'!A:L,12,FALSE) -> 603757 | M2: =VLOOKUP(A2,'Tableau single and bulk'!A:AA,27,FALSE) -> eircom Limited AVC Scheme
A3: 010928M | B3: Vestas Ireland Limited | C3: Add Members | D3: 2025-10-13 14:26:34.155000Z | E3: 010928M | F3: Completed | G3: Active | H3: =VLOOKUP(A3,'Export Worksheet'!A:L,6,FALSE) -> 1 | I3: =VLOOKUP(A3,'Tableau single and bulk'!A:B,2,FALSE) -> NEBAUTO | K3: =VLOOKUP(A3,'Tableau single and bulk'!A:I,9,FALSE) -> 45943.643 | L3: =VLOOKUP(A3,'Tableau single and bulk'!A:L,12,FALSE) -> 603026 | M3: =VLOOKUP(A3,'Tableau single and bulk'!A:AA,27,FALSE) -> Vestas Ireland Limited
A4: 010931M | B4: Kerry Group Plc | C4: Add Members | D4: 2025-10-13 11:20:00.790000Z | E4: 010931M | F4: Completed | G4: Active | H4: =VLOOKUP(A4,'Export Worksheet'!A:L,6,FALSE) -> 27 | I4: =VLOOKUP(A4,'Tableau single and bulk'!A:B,2,FALSE) -> NEBAUTO | K4: =VLOOKUP(A4,'Tableau single and bulk'!A:I,9,FALSE) -> 45943.514 | L4: =VLOOKUP(A4,'Tableau single and bulk'!A:L,12,FALSE) -> 605376 | M4: =VLOOKUP(A4,'Tableau single and bulk'!A:AA,27,FALSE) -> Kerry Dairy Holdings (Ireland) Limited
A5: 010991M | B5: Joseph G Byrne and Sons Consulting Actuaries | C5: Add Members | D5: 2025-10-10 14:44:33.244000Z | E5: 010991M | F5: Completed | G5: Active | H5: =VLOOKUP(A5,'Export Worksheet'!A:L,6,FALSE) -> 1 | I5: =VLOOKUP(A5,'Tableau single and bulk'!A:B,2,FALSE) -> NEBAUTO | K5: =VLOOKUP(A5,'Tableau single and bulk'!A:I,9,FALSE) -> 45940.656 | L5: =VLOOKUP(A5,'Tableau single and bulk'!A:L,12,FALSE) -> 609763 | M5: =VLOOKUP(A5,'Tableau single and bulk'!A:AA,27,FALSE) -> Belvedere College SJ
A6: 010996M | B6: Stryker Ireland | C6: Add Members | D6: 2025-10-13 14:08:22.973000Z | E6: 010996M | F6: Completed | G6: Active | H6: =VLOOKUP(A6,'Export Worksheet'!A:L,6,FALSE) -> 66 | I6: =VLOOKUP(A6,'Tableau single and bulk'!A:B,2,FALSE) -> NEBAUTO | K6: =VLOOKUP(A6,'Tableau single and bulk'!A:I,9,FALSE) -> 45943.631 | L6: =VLOOKUP(A6,'Tableau single and bulk'!A:L,12,FALSE) -> 603990 | M6: =VLOOKUP(A6,'Tableau single and bulk'!A:AA,27,FALSE) -> Stryker Ireland DC Pension Plan
A7: 010998M | B7: Stryker Ireland | C7: Add Members | D7: 2025-10-13 10:53:45.084000Z | E7: 010998M | F7: Completed | G7: Active | H7: =VLOOKUP(A7,'Export Worksheet'!A:L,6,FALSE) -> 2 | I7: =VLOOKUP(A7,'Tableau single and bulk'!A:B,2,FALSE) -> NEBAUTO | K7: =VLOOKUP(A7,'Tableau single and bulk'!A:I,9,FALSE) -> 45943.496 | L7: =VLOOKUP(A7,'Tableau single and bulk'!A:L,12,FALSE) -> 602167 | M7: =VLOOKUP(A7,'Tableau single and bulk'!A:AA,27,FALSE) -> Stryker Ireland Limited Pension Scheme
A8: 011003M | B8: PHX Ireland Group Limited | C8: Add Members | D8: 2025-10-09 19:52:22.884000Z | E8: 011003M | F8: Completed | G8: Active | H8: =VLOOKUP(A8,'Export Worksheet'!A:L,6,FALSE) -> #N/A | I8: =VLOOKUP(A8,'Tableau single and bulk'!A:B,2,FALSE) -> NESAUTO | K8: =VLOOKUP(A8,'Tableau single and bulk'!A:I,9,FALSE) -> 45939.87 | L8: =VLOOKUP(A8,'Tableau single and bulk'!A:L,12,FALSE) -> 609838 | M8: =VLOOKUP(A8,'Tableau single and bulk'!A:AA,27,FALSE) -> PHX Ireland Group Limited
A9: 011007M | B9: Kerry Group Plc | C9: Add Members | D9: 2025-10-13 11:53:50.392000Z | E9: 011007M | F9: Completed | G9: Active | H9: =VLOOKUP(A9,'Export Worksheet'!A:L,6,FALSE) -> 50 | I9: =VLOOKUP(A9,'Tableau single and bulk'!A:B,2,FALSE) -> NEBAUTO | K9: =VLOOKUP(A9,'Tableau single and bulk'!A:I,9,FALSE) -> 45943.537 | L9: =VLOOKUP(A9,'Tableau single and bulk'!A:L,12,FALSE) -> 603888 | M9: =VLOOKUP(A9,'Tableau single and bulk'!A:AA,27,FALSE) -> Kerry Group Plc
A10: 011018M | B10: Aon | C10: Add Members | D10: 2025-10-10 16:28:04.193000Z | E10: 011018M | F10: Completed | G10: Active | H10: =VLOOKUP(A10,'Export Worksheet'!A:L,6,FALSE) -> #N/A | I10: =VLOOKUP(A10,'Tableau single and bulk'!A:B,2,FALSE) -> NESAUTO | K10: =VLOOKUP(A10,'Tableau single and bulk'!A:I,9,FALSE) -> 45940.728 | L10: =VLOOKUP(A10,'Tableau single and bulk'!A:L,12,FALSE) -> 609805 | M10: =VLOOKUP(A10,'Tableau single and bulk'!A:AA,27,FALSE) -> Aztec Financial Services (Irl) Limited
A11: 011019M | B11: Aon | C11: Add Members | D11: 2025-10-13 08:54:47.413000Z | E11: 011019M | F11: Completed | G11: Active | H11: =VLOOKUP(A11,'Export Worksheet'!A:L,6,FALSE) -> #N/A | I11: =VLOOKUP(A11,'Tableau single and bulk'!A:B,2,FALSE) -> NESAUTO | K11: =VLOOKUP(A11,'Tableau single and bulk'!A:I,9,FALSE) -> 45943.413 | L11: =VLOOKUP(A11,'Tableau single and bulk'!A:L,12,FALSE) -> 609805 | M11: =VLOOKUP(A11,'Tableau single and bulk'!A:AA,27,FALSE) -> Aztec Financial Services (Irl) Limited
A12: 011021M | B12: Unio Employee Benefits | C12: Add Members | D12: 2025-10-13 11:01:28.096000Z | E12: 011021M | F12: Completed | G12: Active | H12: =VLOOKUP(A12,'Export Worksheet'!A:L,6,FALSE) -> #N/A | I12: =VLOOKUP(A12,'Tableau single and bulk'!A:B,2,FALSE) -> NESAUTO | K12: =VLOOKUP(A12,'Tableau single and bulk'!A:I,9,FALSE) -> 45943.501 | L12: =VLOOKUP(A12,'Tableau single and bulk'!A:L,12,FALSE) -> 603261 | M12: =VLOOKUP(A12,'Tableau single and bulk'!A:AA,27,FALSE) -> Euler Hermes Services Ireland Ltd
A13: 011040M | B13: Irish Life | C13: Add Members | D13: 2025-10-13 14:56:26.403000Z | E13: 011040M | F13: Completed | G13: Active | H13: =VLOOKUP(A13,'Export Worksheet'!A:L,6,FALSE) -> 1 | I13: =VLOOKUP(A13,'Tableau single and bulk'!A:B,2,FALSE) -> NEBAUTO | K13: =VLOOKUP(A13,'Tableau single and bulk'!A:I,9,FALSE) -> 45943.664 | L13: =VLOOKUP(A13,'Tableau single and bulk'!A:L,12,FALSE) -> 603616 | M13: =VLOOKUP(A13,'Tableau single and bulk'!A:AA,27,FALSE) -> Google Ireland Limited
A14: 011045M | B14: Irish Life | C14: Add Members | D14: 2025-10-08 13:58:50.820000Z | E14: 011045M | F14: Completed | G14: Active | H14: =VLOOKUP(A14,'Export Worksheet'!A:L,6,FALSE) -> 1 | I14: =VLOOKUP(A14,'Tableau single and bulk'!A:B,2,FALSE) -> NEBAUTO | K14: =VLOOKUP(A14,'Tableau single and bulk'!A:I,9,FALSE) -> 45938.624 | L14: =VLOOKUP(A14,'Tableau single and bulk'!A:L,12,FALSE) -> 603640 | M14: =VLOOKUP(A14,'Tableau single and bulk'!A:AA,27,FALSE) -> Petrogas Group Limited
A15: 011049M | B15: Irish Life | C15: Add Members | D15: 2025-10-10 09:34:21.060000Z | E15: 011049M | F15: Completed | G15: Active | H15: =VLOOKUP(A15,'Export Worksheet'!A:L,6,FALSE) -> #N/A | I15: =VLOOKUP(A15,'Tableau single and bulk'!A:B,2,FALSE) -> NEBAUTO | K15: =VLOOKUP(A15,'Tableau single and bulk'!A:I,9,FALSE) -> 45940.44 | L15: =VLOOKUP(A15,'Tableau single and bulk'!A:L,12,FALSE) -> 608020 | M15: =VLOOKUP(A15,'Tableau single and bulk'!A:AA,27,FALSE) -> Renaissance Services of Europe Limited | N15: Batch was deleted
A16: 011053M | B16: Irish Life | C16: Add Members | D16: 2025-10-08 14:02:42.025000Z | E16: 011053M | F16: Completed | G16: Active | H16: =VLOOKUP(A16,'Export Worksheet'!A:L,6,FALSE) -> 1 | I16: =VLOOKUP(A16,'Tableau single and bulk'!A:B,2,FALSE) -> NEBAUTO | K16: =VLOOKUP(A16,'Tableau single and bulk'!A:I,9,FALSE) -> 45938.627 | L16: =VLOOKUP(A16,'Tableau single and bulk'!A:L,12,FALSE) -> 603640 | M16: =VLOOKUP(A16,'Tableau single and bulk'!A:AA,27,FALSE) -> Petrogas Group Limited
A17: 011054M | B17: Irish Life | C17: Add Members | D17: 2025-10-10 11:03:47.641000Z | E17: 011054M | F17: Completed | G17: Active | H17: =VLOOKUP(A17,'Export Worksheet'!A:L,6,FALSE) -> 29 | I17: =VLOOKUP(A17,'Tableau single and bulk'!A:B,2,FALSE) -> NEBAUTO | K17: =VLOOKUP(A17,'Tableau single and bulk'!A:I,9,FALSE) -> 45940.503 | L17: =VLOOKUP(A17,'Tableau single and bulk'!A:L,12,FALSE) -> 609862 | M17: =VLOOKUP(A17,'Tableau single and bulk'!A:AA,27,FALSE) -> Dunnes Stores Unlimited Company
A18: 011071M | B18: Aon | C18: Add Members | D18: 2025-10-13 10:48:52.266000Z | E18: 011071M | F18: Completed | G18: Active | H18: =VLOOKUP(A18,'Export Worksheet'!A:L,6,FALSE) -> #N/A | I18: =VLOOKUP(A18,'Tableau single and bulk'!A:B,2,FALSE) -> NESAUTO | K18: =VLOOKUP(A18,'Tableau single and bulk'!A:I,9,FALSE) -> 45943.492 | L18: =VLOOKUP(A18,'Tableau single and bulk'!A:L,12,FALSE) -> 609844 | M18: =VLOOKUP(A18,'Tableau single and bulk'!A:AA,27,FALSE) -> Kitman Labs Limited
A19: 011072M | B19: Coupa Operations Inc | C19: Add Members | D19: 2025-10-10 16:18:16.800000Z | E19: 011072M | F19: Completed | G19: Active | H19: =VLOOKUP(A19,'Export Worksheet'!A:L,6,FALSE) -> 1 | I19: =VLOOKUP(A19,'Tableau single and bulk'!A:B,2,FALSE) -> NEBAUTO | K19: =VLOOKUP(A19,'Tableau single and bulk'!A:I,9,FALSE) -> 45940.721 | L19: =VLOOKUP(A19,'Tableau single and bulk'!A:L,12,FALSE) -> 603485 | M19: =VLOOKUP(A19,'Tableau single and bulk'!A:AA,27,FALSE) -> Coupa Operations Inc.
A20: 011088M | B20: Munster Cattle Breeding Group Ltd | C20: Add Members | D20: 2025-10-13 10:40:24.006000Z | E20: 011088M | F20: Completed | G20: Active | H20: =VLOOKUP(A20,'Export Worksheet'!A:L,6,FALSE) -> #N/A | I20: =VLOOKUP(A20,'Tableau single and bulk'!A:B,2,FALSE) -> NESAUTO | K20: =VLOOKUP(A20,'Tableau single and bulk'!A:I,9,FALSE) -> 45943.486 | L20: =VLOOKUP(A20,'Tableau single and bulk'!A:L,12,FALSE) -> 602712 | M20: =VLOOKUP(A20,'Tableau single and bulk'!A:AA,27,FALSE) -> MUNSTER CATTLE BREEDING GROUP LTD
A21: 011093M | B21: Irish Life | C21: Add Members | D21: 2025-10-08 14:42:15.155000Z | E21: 011093M | F21: Completed | G21: Active | H21: =VLOOKUP(A21,'Export Worksheet'!A:L,6,FALSE) -> 1 | I21: =VLOOKUP(A21,'Tableau single and bulk'!A:B,2,FALSE) -> NEBAUTO | K21: =VLOOKUP(A21,'Tableau single and bulk'!A:I,9,FALSE) -> 45938.654 | L21: =VLOOKUP(A21,'Tableau single and bulk'!A:L,12,FALSE) -> 603914 | M21: =VLOOKUP(A21,'Tableau single and bulk'!A:AA,27,FALSE) -> Capventis Limited
A22: 011105M | B22: Paddy Denby Engineering Ltd | C22: Add Members | D22: 2025-10-16 13:31:31.639000Z | E22: 011105M | F22: Completed | G22: Active | H22: =VLOOKUP(A22,'Export Worksheet'!A:L,6,FALSE) -> 6 | I22: =VLOOKUP(A22,'Tableau single and bulk'!A:B,2,FALSE) -> NEBAUTO | K22: =VLOOKUP(A22,'Tableau single and bulk'!A:I,9,FALSE) -> 45946.605 | L22: =VLOOKUP(A22,'Tableau single and bulk'!A:L,12,FALSE) -> 601157 | M22: =VLOOKUP(A22,'Tableau single and bulk'!A:AA,27,FALSE) -> Paddy Denby Engineering Ltd
A23: 011109M | B23: WTW | C23: Add Members | D23: 2025-10-10 09:55:27.962000Z | E23: 011109M | F23: Completed | G23: Active | H23: =VLOOKUP(A23,'Export Worksheet'!A:L,6,FALSE) -> 1 | I23: =VLOOKUP(A23,'Tableau single and bulk'!A:B,2,FALSE) -> NEBAUTO | K23: =VLOOKUP(A23,'Tableau single and bulk'!A:I,9,FALSE) -> 45940.455 | L23: =VLOOKUP(A23,'Tableau single and bulk'!A:L,12,FALSE) -> 602420 | M23: =VLOOKUP(A23,'Tableau single and bulk'!A:AA,27,FALSE) -> Netgear International Limited
A24: 011140M | B24: Irish Life | C24: Add Members | D24: 2025-10-13 14:00:06.147000Z | E24: 011140M | F24: Completed | G24: Active | H24: =VLOOKUP(A24,'Export Worksheet'!A:L,6,FALSE) -> #N/A | I24: =VLOOKUP(A24,'Tableau single and bulk'!A:B,2,FALSE) -> NEBAUTO | K24: =VLOOKUP(A24,'Tableau single and bulk'!A:I,9,FALSE) -> 45943.625 | L24: =VLOOKUP(A24,'Tableau single and bulk'!A:L,12,FALSE) -> 603524 | M24: =VLOOKUP(A24,'Tableau single and bulk'!A:AA,27,FALSE) -> Riot Games Limited | N24: Nothing loaded | O24: hard to follow from Midas what happened - Multiple Bulk Items created
A25: 011154M | B25: Veolia UK and Ireland | C25: Add Members | D25: 2025-10-10 10:50:01.254000Z | E25: 011154M | F25: Completed | G25: Active | H25: =VLOOKUP(A25,'Export Worksheet'!A:L,6,FALSE) -> 9 | I25: =VLOOKUP(A25,'Tableau single and bulk'!A:B,2,FALSE) -> NEBAUTO | K25: =VLOOKUP(A25,'Tableau single and bulk'!A:I,9,FALSE) -> 45940.493 | L25: =VLOOKUP(A25,'Tableau single and bulk'!A:L,12,FALSE) -> 602377 | M25: =VLOOKUP(A25,'Tableau single and bulk'!A:AA,27,FALSE) -> Veolia Energy Ser Ireland Ltd
A26: 011155M | B26: Lockton Employee Benefits Ireland | C26: Add Members | D26: 2025-10-13 10:24:20.642000Z | E26: 011155M | F26: Completed | G26: Active | H26: =VLOOKUP(A26,'Export Worksheet'!A:L,6,FALSE) -> #N/A | I26: =VLOOKUP(A26,'Tableau single and bulk'!A:B,2,FALSE) -> NESAUTO | K26: =VLOOKUP(A26,'Tableau single and bulk'!A:I,9,FALSE) -> 45943.475 | L26: =VLOOKUP(A26,'Tableau single and bulk'!A:L,12,FALSE) -> 603651 | M26: =VLOOKUP(A26,'Tableau single and bulk'!A:AA,27,FALSE) -> Specialist Technical Engineering Serv.
A27: 011159M | B27: Irish Life | C27: Add Members | D27: 2025-10-08 17:22:23.724000Z | E27: 011159M | F27: Completed | G27: Active | H27: =VLOOKUP(A27,'Export Worksheet'!A:L,6,FALSE) -> 24 | I27: =VLOOKUP(A27,'Tableau single and bulk'!A:B,2,FALSE) -> NEBAUTO | K27: =VLOOKUP(A27,'Tableau single and bulk'!A:I,9,FALSE) -> 45938.765 | L27: =VLOOKUP(A27,'Tableau single and bulk'!A:L,12,FALSE) -> 603358 | M27: =VLOOKUP(A27,'Tableau single and bulk'!A:AA,27,FALSE) -> Arachas Corporate Brokers Ltd
A28: 011192M | B28: Cathedral Financial Consultants Ltd | C28: Add Members | D28: 2025-10-13 15:10:47.193000Z | E28: 011192M | F28: Completed | G28: Active | H28: =VLOOKUP(A28,'Export Worksheet'!A:L,6,FALSE) -> 17 | I28: =VLOOKUP(A28,'Tableau single and bulk'!A:B,2,FALSE) -> NEBAUTO | K28: =VLOOKUP(A28,'Tableau single and bulk'!A:I,9,FALSE) -> 45943.674 | L28: =VLOOKUP(A28,'Tableau single and bulk'!A:L,12,FALSE) -> 603578 | M28: =VLOOKUP(A28,'Tableau single and bulk'!A:AA,27,FALSE) -> Vow Europe Limited
A29: 011335M | B29: Castlehitt Limited | C29: Add Members | D29: 2025-10-13 14:19:32.375000Z | E29: 011335M | F29: Completed | G29: Active | H29: =VLOOKUP(A29,'Export Worksheet'!A:L,6,FALSE) -> #N/A | I29: =VLOOKUP(A29,'Tableau single and bulk'!A:B,2,FALSE) -> NESAUTO | K29: =VLOOKUP(A29,'Tableau single and bulk'!A:I,9,FALSE) -> 45943.638 | L29: =VLOOKUP(A29,'Tableau single and bulk'!A:L,12,FALSE) -> 605381 | M29: =VLOOKUP(A29,'Tableau single and bulk'!A:AA,27,FALSE) -> Castlehitt Limited
A30: 011341M | B30: Beacon Hospital Sandyford Limited | C30: Add Members | D30: 2025-10-14 11:23:32.269000Z | E30: 011341M | F30: Completed | G30: Active | H30: =VLOOKUP(A30,'Export Worksheet'!A:L,6,FALSE) -> 22 | I30: =VLOOKUP(A30,'Tableau single and bulk'!A:B,2,FALSE) -> NEBAUTO | K30: =VLOOKUP(A30,'Tableau single and bulk'!A:I,9,FALSE) -> 45944.516 | L30: =VLOOKUP(A30,'Tableau single and bulk'!A:L,12,FALSE) -> 602375 | M30: =VLOOKUP(A30,'Tableau single and bulk'!A:AA,27,FALSE) -> Beacon Hospital
A31: 011352M | B31: Brown Thomas and Co Limited | C31: Add Members | D31: 2025-10-14 14:43:18.308000Z | E31: 011352M | F31: Completed | G31: Active | H31: =VLOOKUP(A31,'Export Worksheet'!A:L,6,FALSE) -> 5 | I31: =VLOOKUP(A31,'Tableau single and bulk'!A:B,2,FALSE) -> NEBAUTO | K31: =VLOOKUP(A31,'Tableau single and bulk'!A:I,9,FALSE) -> 45944.655 | L31: =VLOOKUP(A31,'Tableau single and bulk'!A:L,12,FALSE) -> 602903 | M31: =VLOOKUP(A31,'Tableau single and bulk'!A:AA,27,FALSE) -> Brown Thomas Arnotts Limited
A32: 011355M | B32: Patrick J Tobin Ltd | C32: Add Members | D32: 2025-10-11 10:21:39.372000Z | E32: 011355M | F32: Completed | G32: Active | H32: =VLOOKUP(A32,'Export Worksheet'!A:L,6,FALSE) -> #N/A | I32: =VLOOKUP(A32,'Tableau single and bulk'!A:B,2,FALSE) -> NESAUTO | K32: =VLOOKUP(A32,'Tableau single and bulk'!A:I,9,FALSE) -> 45941.473 | L32: =VLOOKUP(A32,'Tableau single and bulk'!A:L,12,FALSE) -> 602944 | M32: =VLOOKUP(A32,'Tableau single and bulk'!A:AA,27,FALSE) -> PATRICK J TOBIN LTD
A33: 011356M | B33: Patrick J Tobin Ltd | C33: Add Members | D33: 2025-10-11 10:17:43.024000Z | E33: 011356M | F33: Completed | G33: Active | H33: =VLOOKUP(A33,'Export Worksheet'!A:L,6,FALSE) -> #N/A | I33: =VLOOKUP(A33,'Tableau single and bulk'!A:B,2,FALSE) -> NESAUTO | K33: =VLOOKUP(A33,'Tableau single and bulk'!A:I,9,FALSE) -> 45941.471 | L33: =VLOOKUP(A33,'Tableau single and bulk'!A:L,12,FALSE) -> 602944 | M33: =VLOOKUP(A33,'Tableau single and bulk'!A:AA,27,FALSE) -> PATRICK J TOBIN LTD
A34: 011357M | B34: Patrick J Tobin Ltd | C34: Add Members | D34: 2025-10-11 10:20:48.880000Z | E34: 011357M | F34: Completed | G34: Active | H34: =VLOOKUP(A34,'Export Worksheet'!A:L,6,FALSE) -> #N/A | I34: =VLOOKUP(A34,'Tableau single and bulk'!A:B,2,FALSE) -> NESAUTO | K34: =VLOOKUP(A34,'Tableau single and bulk'!A:I,9,FALSE) -> 45941.473 | L34: =VLOOKUP(A34,'Tableau single and bulk'!A:L,12,FALSE) -> 602944 | M34: =VLOOKUP(A34,'Tableau single and bulk'!A:AA,27,FALSE) -> PATRICK J TOBIN LTD
A35: 011358M | B35: Patrick J Tobin Ltd | C35: Add Members | D35: 2025-10-11 09:42:59.881000Z | E35: 011358M | F35: Completed | G35: Active | H35: =VLOOKUP(A35,'Export Worksheet'!A:L,6,FALSE) -> #N/A | I35: =VLOOKUP(A35,'Tableau single and bulk'!A:B,2,FALSE) -> NESAUTO | K35: =VLOOKUP(A35,'Tableau single and bulk'!A:I,9,FALSE) -> 45941.446 | L35: =VLOOKUP(A35,'Tableau single and bulk'!A:L,12,FALSE) -> 602944 | M35: =VLOOKUP(A35,'Tableau single and bulk'!A:AA,27,FALSE) -> PATRICK J TOBIN LTD
A36: 011359M | B36: Apleona Ireland Limited | C36: Add Members | D36: 2025-10-13 10:52:44.481000Z | E36: 011359M | F36: Completed | G36: Active | H36: =VLOOKUP(A36,'Export Worksheet'!A:L,6,FALSE) -> 1 | I36: =VLOOKUP(A36,'Tableau single and bulk'!A:B,2,FALSE) -> NEBAUTO | K36: =VLOOKUP(A36,'Tableau single and bulk'!A:I,9,FALSE) -> 45943.495 | L36: =VLOOKUP(A36,'Tableau single and bulk'!A:L,12,FALSE) -> 606934 | M36: =VLOOKUP(A36,'Tableau single and bulk'!A:AA,27,FALSE) -> Apleona Ireland Limited
... A41: 011391M | B41: Roadstone Limited | C41: Add Members | D41: 2025-10-13 09:42:16.436000Z | E41: 011391M | F41: Completed | G41: Active | H41: =VLOOKUP(A41,'Export Worksheet'!A:L,6,FALSE) -> #N/A | I41: =VLOOKUP(A41,'Tableau single and bulk'!A:B,2,FALSE) -> NESAUTO | K41: =VLOOKUP(A41,'Tableau single and bulk'!A:I,9,FALSE) -> 45943.446 | L41: =VLOOKUP(A41,'Tableau single and bulk'!A:L,12,FALSE) -> 602719 | M41: =VLOOKUP(A41,'Tableau single and bulk'!A:AA,27,FALSE) -> Roadstone Limited
A42: 011392M | B42: Irish Life | C42: Add Members | D42: 2025-10-14 09:35:08.886000Z | E42: 011392M | F42: Completed | G42: Active | H42: =VLOOKUP(A42,'Export Worksheet'!A:L,6,FALSE) -> #N/A | I42: =VLOOKUP(A42,'Tableau single and bulk'!A:B,2,FALSE) -> NEBAUTO | K42: =VLOOKUP(A42,'Tableau single and bulk'!A:I,9,FALSE) -> 45944.441 | L42: =VLOOKUP(A42,'Tableau single and bulk'!A:L,12,FALSE) -> 603783 | M42: =VLOOKUP(A42,'Tableau single and bulk'!A:AA,27,FALSE) -> Kverneland Group Ireland Limited | N42: errors found
A43: 011396M | B43: Irish Life | C43: Add Members | D43: 2025-10-15 08:18:04.397000Z | E43: 011396M | F43: Completed | G43: Active | H43: =VLOOKUP(A43,'Export Worksheet'!A:L,6,FALSE) -> 7 | I43: =VLOOKUP(A43,'Tableau single and bulk'!A:B,2,FALSE) -> NEBAUTO | K43: =VLOOKUP(A43,'Tableau single and bulk'!A:I,9,FALSE) -> 45945.387 | L43: =VLOOKUP(A43,'Tableau single and bulk'!A:L,12,FALSE) -> 609743 | M43: =VLOOKUP(A43,'Tableau single and bulk'!A:AA,27,FALSE) -> Motorola Solutions UK Ltd (Irl Branch)
A44: 011400M | B44: Irish Life | C44: Add Members | D44: 2025-10-09 10:10:19.998000Z | E44: 011400M | F44: Completed | G44: Active | H44: =VLOOKUP(A44,'Export Worksheet'!A:L,6,FALSE) -> 3 | I44: =VLOOKUP(A44,'Tableau single and bulk'!A:B,2,FALSE) -> NEBAUTO | K44: =VLOOKUP(A44,'Tableau single and bulk'!A:I,9,FALSE) -> 45939.465 | L44: =VLOOKUP(A44,'Tableau single and bulk'!A:L,12,FALSE) -> 603612 | M44: =VLOOKUP(A44,'Tableau single and bulk'!A:AA,27,FALSE) -> Stauntons Pharmacy Limited
...

Sheet Tableau single and bulk
A1: Midas Number | B1: Worktype | C1: Service Calculation | D1: Service Summary | E1: Allocated User | F1: Broker Code | G1: Completed By ID | H1: Completed date range | I1: Date Completed | J1: DC Teams | K1: Member Number | L1: Scheme Number | M1: Select Context | N1: TP2V3_WI_EFFORT | O1: TP2V3_WI_ORIGINATOR | P1: TP2V3_WI_SOURCE | Q1: Worktype Description | R1: Worktype TYPE | S1: Allocated Team | T1: Context | U1: Date Created | V1: Process Deadline | W1: Number of Records | X1: Turnaround Time | Y1: Broker Name | Z1: Object_ID | AA1: Scheme Name | AB1: Status | AC1: TP2V3_DESCRIPTION | AD1: TP2V3_SOURCE_INTEXT | AE1: TP2V3_WI_BREAKDOWN_TOTAL | AF1: TP2V3_WI_EFFORT_QC | AG1: TP2V3_WI_PEND_REASON | AH1: TP2V3_WI_QC_CHECKER | AI1: TP2V3_WI_QC_COMP_DATE | AJ1: TP2V3_WI_QC_COMPLETE | AK1: TP2V3_WI_QC_RESULT | AL1: TP2V3_WI_QC_RESULT_INIT | AM1: TP2V3_WI_QC_ROOT_CAUSE | AN1: TP2V3_WI_QC_USER | AO1: TP2V3_WI_TEAM_CODE | AP1: WI_CLI_INDICATOR
A2: 010921M | B2: NESAUTO | C2: Day 4 | D2: In Service | E2: Y337 | F2: A300 | G2: Y337 | H2: TRUE | I2: 45943.593 | J2: Auto Enrolment DC | K2: 1201945 | L2: 603757 | M2: DC | P2: SecureShare eircom | Q2: DC | R2: 1 | S2: Auto Enrolment DC | T2: DC | U2: 45938.468 | V2: 45943.958 | W2: 1 | X2: 3.124919 | Y2: ILFS Corporate Business | Z2: 25281CBPR02EF52 | AA2: eircom Limited AVC Scheme | AB2: Completed | AC2: John Fitzgerald - added 1201945 | AD2: INTERNAL | AE2: 1 | AO2: TM32 | AP2: N
A3: 010928M | B3: NEBAUTO | C3: Day 4 | D3: In Service | E3: C192 | F3: S168 | G3: C192 | H3: TRUE | I3: 45943.643 | J3: Auto Enrolment DC | L3: 603026 | M3: DC | P3: SecureShare Vestas I | Q3: DC | R3: 1 | S3: Auto Enrolment DC | T3: DC | U3: 45938.474 | V3: 45943.958 | W3: 1 | X3: 3.1693171 | Y3: Mercer (Elect Existing Business) | Z3: 25281CBPR02EFE2 | AA3: Vestas Ireland Limited | AB3: Completed | AC3: Employer: Vestas Ireland LTD :: Number of Members: 1 | AD3: INTERNAL | AE3: 1 | AO3: TM30 | AP3: N
A4: 010931M | B4: NEBAUTO | C4: Day 4 | D4: In Service | E4: Y337 | F4: A300 | G4: Y337 | H4: TRUE | I4: 45943.514 | J4: Auto Enrolment DC | L4: 605376 | M4: DC | P4: SecureShare Kerry Gr | Q4: DC | R4: 1 | S4: Auto Enrolment DC | T4: DC | U4: 45938.477 | V4: 45943.958 | W4: 1 | X4: 3.0367477 | Y4: ILFS Corporate Business | Z4: 25281CBPR02F032 | AA4: Kerry Dairy Holdings (Ireland) Limited | AB4: Completed | AC4: 27 NEs N/A :: Number of Members: N/A | AD4: INTERNAL | AE4: 1 | AO4: TM32 | AP4: N
A5: 010937M | B5: NESAUTO | C5: Day 5 + | D5: In Service | E5: F243 | F5: RT02 | G5: F243 | H5: TRUE | I5: 45949.586 | J5: Auto Enrolment DC | K5: 4005562 | L5: 602631 | M5: DC | P5: SecureShare Society | Q5: DC | R5: 1 | S5: Auto Enrolment DC | T5: DC | U5: 45938.479 | V5: 45950.958 | W5: 1 | X5: 7.1076157 | Y5: PWC Financial Consulting DAC | Z5: 25281CBPR02F082 | AA5: Society of Saint Vincent De Paul | AB5: Completed | AC5: Employer: Society of Saint Vincent de Paul :: ... (see attached file for full description) | AD5: INTERNAL | AE5: 1 | AO5: TM33 | AP5: N
A6: 010991M | B6: NEBAUTO | C6: Day 3 | D6: In Service | E6: X967 | F6: TU84 | G6: x967 | H6: TRUE | I6: 45940.656 | J6: Auto Enrolment DC | L6: 609763 | M6: DC | P6: SecureShare Joseph G | Q6: DC | R6: 1 | S6: Auto Enrolment DC | T6: DC | U6: 45938.531 | V6: 45943.958 | W6: 1 | X6: 2.1247801 | Y6: Joseph G. Byrne & Sons Consulting | Z6: 25281CBPR02F4B7 | AA6: Belvedere College SJ | AB6: Completed | AC6: Molly O'Hare | AD6: INTERNAL | AE6: 1 | AO6: TM07 | AP6: N
A7: 010996M | B7: NEBAUTO | C7: Day 4 | D7: In Service | E7: Y337 | F7: A300 | G7: Y337 | H7: TRUE | I7: 45943.631 | J7: Auto Enrolment DC | L7: 603990 | M7: DC | P7: SecureShare Stryker | Q7: DC | R7: 1 | S7: Auto Enrolment DC | T7: DC | U7: 45938.532 | V7: 45943.958 | W7: 1 | X7: 3.0985532 | Y7: ILFS Corporate Business | Z7: 25281CBPR02F4B8 | AA7: Stryker Ireland DC Pension Plan | AB7: Completed | AC7: 66 NEs N/A :: Number of Members: N/A | AD7: INTERNAL | AE7: 1 | AO7: TM32 | AP7: N
A8: 010998M | B8: NEBAUTO | C8: Day 3 | D8: In Service | E8: Y337 | F8: A300 | G8: Y337 | H8: TRUE | I8: 45943.496 | J8: Auto Enrolment DC | L8: 602167 | M8: DC | P8: SecureShare Stryker | Q8: DC | R8: 1 | S8: Auto Enrolment DC | T8: DC | U8: 45938.533 | V8: 45943.958 | W8: 1 | X8: 2.9623611 | Y8: ILFS Corporate Business | Z8: 25281CBPR02F4ED | AA8: Stryker Ireland Limited Pension Scheme | AB8: Completed | AC8: 2 NEs N/A :: Number of Members: N/A | AD8: INTERNAL | AE8: 1 | AO8: TM32 | AP8: N
A9: 011003M | B9: NESAUTO | C9: Day 2 | D9: In Service | E9: J987 | F9: NK89 | G9: J987 | H9: TRUE | I9: 45939.87 | J9: Auto Enrolment DC | K9: 1201450 | L9: 609838 | M9: DC | P9: SecureShare PHX Irel | Q9: DC | R9: 1 | S9: Auto Enrolment DC | T9: DC | U9: 45938.536 | V9: 45943.958 | W9: 1 | X9: 1.3339815 | Y9: Aon Ireland Ltd. | Z9: 25281CBPR02F506 | AA9: PHX Ireland Group Limited | AB9: Completed | AC9: Employer: TCP Homecare :: Member Name: Rebekah Duffy :: Date of Birth: 12/09/1992 | AD9: INTERNAL | AE9: 1 | AO9: TM02 | AP9: N
A10: 011007M | B10: NEBAUTO | C10: Day 3 | D10: In Service | E10: Y337 | F10: A300 | G10: Y337 | H10: TRUE | I10: 45943.537 | J10: Auto Enrolment DC | L10: 603888 | M10: DC | P10: SecureShare Kerry Gr | Q10: DC | R10: 1 | S10: Auto Enrolment DC | T10: DC | U10: 45938.542 | V10: 45943.958 | W10: 1 | X10: 2.9952315 | Y10: ILFS Corporate Business | Z10: 25281CBPR02F551 | AA10: Kerry Group Plc | AB10: Completed | AC10: 50 NEs - Kerry Group Services Ltd :: Number of Members: N/A | AD10: INTERNAL | AE10: 1 | AO10: TM32 | AP10: N
A11: 011018M | B11: NESAUTO | C11: Day 3 | D11: In Service | E11: x967 | F11: A612 | G11: x967 | H11: TRUE | I11: 45940.728 | J11: Auto Enrolment DC | K11: 1201694 | L11: 609805 | M11: DC | P11: SecureShare Aon | Q11: DC | R11: 1 | S11: Auto Enrolment DC | T11: DC | U11: 45938.563 | V11: 45943.958 | W11: 1 | X11: 2.1651736 | Y11: Aon Ireland Ltd. | Z11: 25281CBPR02F644 | AA11: Aztec Financial Services (Irl) Limited | AB11: Completed | AC11: Employer: Aztec :: Member Name: Ms Rosie Allemby :: Date of Birth: 08/07/1997 | AD11: INTERNAL | AE11: 1 | AO11: TM01 | AP11: N
A12: 011019M | B12: NESAUTO | C12: Day 3 | D12: In Service | E12: x967 | F12: A612 | G12: x967 | H12: TRUE | I12: 45943.413 | J12: Auto Enrolment DC | K12: 1201746 | L12: 609805 | M12: DC | P12: SecureShare Aon | Q12: DC | R12: 1 | S12: Auto Enrolment DC | T12: DC | U12: 45938.563 | V12: 45943.958 | W12: 1 | X12: 2.8497222 | Y12: Aon Ireland Ltd. | Z12: 25281CBPR02F645 | AA12: Aztec Financial Services (Irl) Limited | AB12: Completed | AC12: Employer: Aztec :: Member Name: Miss Nivethitha Dharmaraja :: Date of Birth: 10/03/1998 | AD12: INTERNAL | AE12: 1 | AO12: TM01 | AP12: N
A13: 011021M | B13: NESAUTO | C13: Day 3 | D13: In Service | E13: S143 | F13: NJ23 | G13: S143 | H13: TRUE | I13: 45943.501 | J13: Auto Enrolment DC | K13: 1201851 | L13: 603261 | M13: DC | P13: SecureShare Unio Emp | Q13: DC | R13: 1 | S13: Auto Enrolment DC | T13: DC | U13: 45938.567 | V13: 45943.958 | W13: 1 | X13: 2.9339352 | Y13: Unio Ltd | Z13: 25281CBPR02F669 | AA13: Euler Hermes Services Ireland Ltd | AB13: Completed | AC13: Sowmiya Dhamodhara 1201851 | AD13: INTERNAL | AE13: 1 | AO13: TM35 | AP13: N
A14: 011040M | B14: NEBAUTO | C14: Day 4 | D14: In Service | E14: F243 | F14: A300 | G14: F243 | H14: TRUE | I14: 45943.664 | J14: Auto Enrolment DC | L14: 603616 | M14: DC | P14: SecureShare Irish Li | Q14: DC | R14: 1 | S14: Auto Enrolment DC | T14: DC | U14: 45938.594 | V14: 45943.958 | W14: 1 | X14: 3.0700579 | Y14: ILFS Corporate Business | Z14: 25281CBPR02F85B | AA14: Google Ireland Limited | AB14: Completed | AC14: Employer: Google :: Number of Members: 1 | AD14: INTERNAL | AE14: 1 | AH14: Y337 | AI14: 45943.65 | AK14: Passed | AL14: Passed | AO14: TM32 | AP14: N
A15: 011045M | B15: NEBAUTO | C15: Day 1 | D15: In Service | E15: X967 | F15: NJ23 | G15: x967 | H15: TRUE | I15: 45938.624 | J15: Auto Enrolment DC | L15: 603640 | M15: DC | P15: SecureShare Irish Li | Q15: DC | R15: 1 | S15: Auto Enrolment DC | T15: DC | U15: 45938.599 | V15: 45943.958 | W15: 1 | X15: 0.025266204 | Y15: Unio Ltd | Z15: 25281CBPR02F8B0 | AA15: Petrogas Group Limited | AB15: Completed | AC15: Julius Majauskas | AD15: INTERNAL | AE15: 1 | AO15: TM35 | AP15: N
A16: 011049M | B16: NEBAUTO | C16: Day 2 | D16: In Service | E16: J905 | F16: A100 | G16: y939 | H16: TRUE | I16: 45940.44 | J16: Auto Enrolment DC | L16: 608020 | M16: DC | P16: SecureShare Irish Li | Q16: DC | R16: 1 | S16: Auto Enrolment DC | T16: DC | U16: 45938.601 | V16: 45943.958 | W16: 1 | X16: 1.8392824 | Y16: ILFS Corporate Business | Z16: 25281CBPR02F8F3 | AA16: Renaissance Services of Europe Limited | AB16: Completed | AC16: Employer: N/A :: Number of Members: N/A | AE16: 1 | AO16: TM05 | AP16: N
A17: 011053M | B17: NEBAUTO | C17: Day 1 | D17: In Service | E17: X967 | F17: NJ23 | G17: x967 | H17: TRUE | I17: 45938.627 | J17: Auto Enrolment DC | L17: 603640 | M17: DC | P17: SecureShare Irish Li | Q17: DC | R17: 1 | S17: Auto Enrolment DC | T17: DC | U17: 45938.604 | V17: 45943.958 | W17: 1 | X17: 0.022858796 | Y17: Unio Ltd | Z17: 25281CBPR02F92C | AA17: Petrogas Group Limited | AB17: Completed | AC17: Lina Rakauske | AD17: INTERNAL | AE17: 1 | AO17: TM35 | AP17: N
A18: 011054M | B18: NEBAUTO | C18: Day 2 | D18: In Service | E18: J987 | F18: A100 | G18: J987 | H18: TRUE | I18: 45940.503 | J18: Auto Enrolment DC | L18: 609862 | M18: DC | P18: SecureShare Irish Li | Q18: DC | R18: 1 | S18: Auto Enrolment DC | T18: DC | U18: 45938.606 | V18: 45943.958 | W18: 1 | X18: 1.8966088 | Y18: ILFS Corporate Business | Z18: 25281CBPR02F92E | AA18: Dunnes Stores Unlimited Company | AB18: Completed | AC18: Employer: Dunnes Stores :: Number of Members: 29 | AD18: INTERNAL | AE18: 1 | AO18: TM33 | AP18: N
A19: 011071M | B19: NESAUTO | C19: Day 3 | D19: In Service | E19: S143 | F19: A612 | G19: S143 | H19: TRUE | I19: 45943.492 | J19: Auto Enrolment DC | K19: 1201798 | L19: 609844 | M19: DC | P19: SecureShare Aon | Q19: DC | R19: 1 | S19: Auto Enrolment DC | T19: DC | U19: 45938.626 | V19: 45943.958 | W19: 1 | X19: 2.8659954 | Y19: Aon Ireland Ltd. | Z19: 25281CBPR02FB70 | AA19: Kitman Labs Limited | AB19: Completed | AC19: Deirbhile OCallaghan 1201798 | AD19: INTERNAL | AE19: 1 | AO19: TM01 | AP19: N
A20: 011072M | B20: NEBAUTO | C20: Day 3 | D20: In Service | E20: X967 | F20: A612 | G20: x967 | H20: TRUE | I20: 45940.721 | J20: Auto Enrolment DC | L20: 603485 | M20: DC | P20: SecureShare Coupa Op | Q20: DC | R20: 1 | S20: Auto Enrolment DC | T20: DC | U20: 45938.626 | V20: 45943.958 | W20: 1 | X20: 2.0944329 | Y20: Aon Ireland Ltd. | Z20: 25281CBPR02FB71 | AA20: Coupa Operations Inc. | AB20: Completed | AC20: Cristina Sala | AD20: INTERNAL | AE20: 1 | AO20: TM01 | AP20: N
A21: 011088M | B21: NESAUTO | C21: Day 3 | D21: In Service | E21: S143 | F21: S168 | G21: S143 | H21: TRUE | I21: 45943.486 | J21: Auto Enrolment DC | K21: 1201797 | L21: 602712 | M21: DC | P21: SecureShare Munster | Q21: DC | R21: 1 | S21: Auto Enrolment DC | T21: DC | U21: 45938.639 | V21: 45943.958 | W21: 1 | X21: 2.8475694 | Y21: Mercer (Elect Existing Business) | Z21: 25281CBPR02FC83 | AA21: MUNSTER CATTLE BREEDING GROUP LTD | AB21: Completed | AC21: Kieran Kelliher1201797 | AD21: INTERNAL | AE21: 1 | AO21: TM02 | AP21: N
A22: 011093M | B22: NEBAUTO | C22: Day 1 | D22: In Service | E22: X967 | F22: NJ23 | G22: x967 | H22: TRUE | I22: 45938.654 | J22: Auto Enrolment DC | L22: 603914 | M22: DC | P22: SecureShare Irish Li | Q22: DC | R22: 1 | S22: Auto Enrolment DC | T22: DC | U22: 45938.642 | V22: 45943.958 | W22: 1 | X22: 0.012546296 | Y22: Unio Ltd | Z22: 25281CBPR02FC84 | AA22: Capventis Limited | AB22: Completed | AC22: Stephen Bourke | AD22: INTERNAL | AE22: 1 | AO22: TM35 | AP22: N
A23: 011103M | B23: NESAUTO | C23: Day 4 | D23: In Service | E23: J987 | F23: TO66 | G23: J987 | H23: TRUE | I23: 45941.674 | J23: Auto Enrolment DC | K23: 1201726 | L23: 603633 | M23: DC | P23: PPI Secure Path | Q23: DC | R23: 1 | S23: Auto Enrolment DC | T23: DC | U23: 45938.65 | V23: 45943.958 | W23: 1 | X23: 3.0239815 | Y23: Mount Street Trustees Ltd | Z23: 25281CBPR02FCE7 | AA23: Nisbets Limited | AB23: Completed | AC23: Tony Slott | AD23: INTERNAL | AE23: 1 | AO23: TM05 | AP23: N
A24: 011105M | B24: NEBAUTO | C24: Day 5 + | D24: In Service | E24: J905 | F24: RM91 | G24: J905 | H24: TRUE | I24: 45946.605 | J24: Auto Enrolment DC | L24: 601157 | M24: DC | N24: 15 | P24: SecureShare Paddy De | Q24: DC | R24: 1 | S24: Auto Enrolment DC | T24: DC | U24: 45938.651 | V24: 45951.958 | W24: 1 | X24: 5.9540509 | Y24: Willis Towers Watson Life & Pensi | Z24: 25281CBPR02FDA3 | AA24: Paddy Denby Engineering Ltd | AB24: Completed | AC24: Employer: paddy denby engineering ltd :: Number of Members: 6 | AD24: INTERNAL | AE24: 1 | AO24: TM07 | AP24: N
A25: 011106M | B25: NESAUTO | C25: Day 4 | D25: In Service | E25: J905 | F25: TO66 | G25: J905 | H25: TRUE | I25: 45943.655 | J25: Auto Enrolment DC | K25: 1201490 | L25: 603633 | M25: DC | N25: 5 | P25: PPI Secure Path | Q25: DC | R25: 1 | S25: Auto Enrolment DC | T25: DC | U25: 45938.652 | V25: 45943.958 | W25: 1 | X25: 3.0030093 | Y25: Mount Street Trustees Ltd | Z25: 25281CBPR02FD14 | AA25: Nisbets Limited | AB25: Completed | AC25: Caroline Barry | AD25: INTERNAL | AE25: 1 | AH25: F243 | AI25: 45943.638 | AK25: Passed | AL25: Passed | AO25: TM05 | AP25: N
A26: 011109M | B26: NEBAUTO | C26: Day 2 | D26: In Service | E26: J905 | F26: RM91 | G26: y939 | H26: TRUE | I26: 45940.455 | J26: Auto Enrolment DC | L26: 602420 | M26: DC | P26: SecureShare WTW | Q26: DC | R26: 1 | S26: Auto Enrolment DC | T26: DC | U26: 45938.653 | V26: 45943.958 | W26: 1 | X26: 1.8019792 | Y26: Willis Towers Watson Life & Pensi | Z26: 25281CBPR02FE22 | AA26: Netgear International Limited | AB26: Completed | AC26: Employer: Net gear :: Number of Members: 1 | AD26: INTERNAL | AE26: 1 | AO26: TM07 | AP26: N
A27: 011110M | B27: NESAUTO | C27: Day 2 | D27: In Service | E27: J905 | F27: TO66 | G27: J905 | H27: TRUE | I27: 45940.426 | J27: Auto Enrolment DC | K27: 1201476 | L27: 603633 | M27: DC | N27: 5 | P27: PPI Secure Path | Q27: DC | R27: 1 | S27: Auto Enrolment DC | T27: DC | U27: 45938.655 | V27: 45943.958 | W27: 1 | X27: 1.7712616 | Y27: Mount Street Trustees Ltd | Z27: 25281CBPR02FD91 | AA27: Nisbets Limited | AB27: Completed | AC27: Nicole Bermingham | AD27: INTERNAL | AE27: 1 | AO27: TM05 | AP27: N
A28: 011114M | B28: NESAUTO | C28: Day 4 | D28: In Service | E28: J987 | F28: TO66 | G28: J987 | H28: TRUE | I28: 45941.666 | J28: Auto Enrolment DC | K28: 1201725 | L28: 603633 | M28: DC | P28: PPI Secure Path | Q28: DC | R28: 1 | S28: Auto Enrolment DC | T28: DC | U28: 45938.656 | V28: 45943.958 | W28: 1 | X28: 3.0104977 | Y28: Mount Street Trustees Ltd | Z28: 25281CBPR02FDD3 | AA28: Nisbets Limited | AB28: Completed | AC28: NE Rachel Lafferty | AD28: INTERNAL | AE28: 1 | AO28: TM05 | AP28: N
A29: 011125M | B29: NESAUTO | C29: Day 4 | D29: In Service | E29: J987 | F29: TO66 | G29: J987 | H29: TRUE | I29: 45941.684 | J29: Auto Enrolment DC | K29: 1201727 | L29: 603633 | M29: DC | P29: PPI Secure Path | Q29: DC | R29: 1 | S29: Auto Enrolment DC | T29: DC | U29: 45938.661 | V29: 45943.958 | W29: 1 | X29: 3.0229977 | Y29: Mount Street Trustees Ltd | Z29: 25281CBPR02FE77 | AA29: Nisbets Limited | AB29: Completed | AD29: INTERNAL | AE29: 1 | AO29: TM05 | AP29: N
A30: 011128M | B30: NESAUTO | C30: Day 4 | D30: In Service | E30: J987 | F30: TO66 | G30: J987 | H30: TRUE | I30: 45941.696 | J30: Auto Enrolment DC | L30: 603633 | M30: DC | P30: PPI Secure Path | Q30: DC | R30: 1 | S30: Auto Enrolment DC | T30: DC | U30: 45938.664 | V30: 45943.958 | W30: 1 | X30: 3.0316667 | Y30: Mount Street Trustees Ltd | Z30: 25281CBPR02FEBE | AA30: Nisbets Limited | AB30: Completed | AC30: Member Added 1201219 | AE30: 1 | AO30: TM05 | AP30: N
A31: 011140M | B31: NEBAUTO | C31: Day 3 | D31: In Service | E31: C192 | F31: A612 | G31: C192 | H31: TRUE | I31: 45943.625 | J31: Auto Enrolment DC | L31: 603524 | M31: DC | P31: SecureShare Irish Li | Q31: DC | R31: 1 | S31: Auto Enrolment DC | T31: DC | U31: 45938.677 | V31: 45943.958 | W31: 1 | X31: 2.9477431 | Y31: Aon Ireland Ltd. | Z31: 25281CBPR030080 | AA31: Riot Games Limited | AB31: Completed | AC31: Employer: N/A :: Number of Members: N/A | AE31: 1 | AH31: x967 | AI31: 45943.537 | AK31: Passed | AL31: Failed | AM31: Detail entered below (5) | AO31: TM12 | AP31: N
A32: 011154M | B32: NEBAUTO | C32: Day 2 | D32: In Service | E32: J905 | F32: A300 | G32: J905 | H32: TRUE | I32: 45940.493 | J32: Auto Enrolment DC | L32: 602377 | M32: DC | N32: 20 | P32: SecureShare Veolia U | Q32: DC | R32: 1 | S32: Auto Enrolment DC | T32: DC | U32: 45938.692 | V32: 45943.958 | W32: 1 | X32: 1.8005903 | Y32: ILFS Corporate Business | Z32: 25281CBPR030170 | AA32: Veolia Energy Ser Ireland Ltd | AB32: Completed | AC32: Employer: Veolia :: Number of Members: N/A | AD32: INTERNAL | AE32: 1 | AO32: TM05 | AP32: N
A33: 011155M | B33: NESAUTO | C33: Day 3 | D33: In Service | E33: S143 | F33: VT80 | G33: S143 | H33: TRUE | I33: 45943.475 | J33: Auto Enrolment DC | K33: 1201791 | L33: 603651 | M33: DC | P33: SecureShare Lockton | Q33: DC | R33: 1 | S33: Auto Enrolment DC | T33: DC | U33: 45938.693 | V33: 45943.958 | W33: 1 | X33: 2.7822106 | Y33: Lockton Insurance Brokers (Irelan | Z33: 25281CBPR0301A2 | AA33: Specialist Technical Engineering Serv. | AB33: Completed | AC33: Veronic McMahon 1201790 | AD33: INTERNAL | AE33: 1 | AO33: TM31 | AP33: N
A34: 011159M | B34: NEBAUTO | C34: Day 1 | D34: In Service | E34: X967 | F34: VO24 | G34: x967 | H34: TRUE | I34: 45938.765 | J34: Auto Enrolment DC | L34: 603358 | M34: DC | P34: SecureShare Irish Li | Q34: DC | R34: 1 | S34: Auto Enrolment DC | T34: DC | U34: 45938.7 | V34: 45943.958 | W34: 1 | X34: 0.065636574 | Y34: Bluechip Financial Consultants Lt | Z34: 25281CBPR0301D9 | AA34: Arachas Corporate Brokers Ltd | AB34: Completed | AC34: 24 x NE - Indexed World Eq Fund x 3 NE | AD34: INTERNAL | AE34: 1 | AO34: TM05 | AP34: N
A35: 011192M | B35: NEBAUTO | C35: Day 3 | D35: In Service | E35: x967 | F35: N847 | G35: C192 | H35: TRUE | I35: 45943.674 | J35: Auto Enrolment DC | L35: 603578 | M35: DC | P35: SecureShare Cathedra | Q35: DC | R35: 1 | S35: Auto Enrolment DC | T35: DC | U35: 45938.727 | V35: 45943.958 | W35: 1 | X35: 2.9474421 | Y35: Cathedral Financial Consultants L | Z35: 25281CBPR0302BD | AA35: Vow Europe Limited | AB35: Completed | AC35: Employer: Vow Europe Ltd :: Number of Members: 17 | AD35: INTERNAL | AE35: 1 | AH35: F243 | AI35: 45943.637 | AK35: Passed | AL35: Passed | AO35: TM07 | AP35: N
A36: 011196M | B36: NESAUTO | C36: Day 5 + | D36: In Service | E36: S143 | F36: RM91 | G36: S143 | H36: TRUE | I36: 45953.52 | J36: Auto Enrolment DC | K36: 1204206 | L36: 605271 | M36: DC | P36: SecureShare Datalec | Q36: DC | R36: 1 | S36: Auto Enrolment DC | T36: DC | U36: 45938.73 | V36: 45959.958 | W36: 1 | X36: 10.790012 | Y36: Willis Towers Watson Life & Pensi | Z36: 25281CBPR0302C9 | AA36: Datalec Precision Installations Limited | AB36: Completed | AC36: Joseph Iribhogbe 1204206 | AD36: INTERNAL | AE36: 1 | AO36: TM07 | AP36: N
A37: 011335M | B37: NESAUTO | C37: Day 3 | D37: In Service | E37: F243 | F37: RT02 | G37: F243 | H37: TRUE | I37: 45943.638 | J37: Auto Enrolment DC | K37: 1202034 | L37: 605381 | M37: DC | P37: SecureShare Castlehi | Q37: DC | R37: 1 | S37: Auto Enrolment DC | T37: DC | U37: 45939.343 | V37: 45946.958 | W37: 1 | X37: 2.2958333 | Y37: PWC Financial Consulting DAC | Z37: 25282CBPR03253A | AA37: Castlehitt Limited | AB37: Completed | AC37: Barry Burtler- Need salary | AD37: INTERNAL | AE37: 1 | AO37: TM01 | AP37: N
A38: 011341M | B38: NEBAUTO | C38: Day 4 | D38: In Service | E38: J905 | F38: E080 | G38: J905 | H38: TRUE | I38: 45944.516 | J38: Auto Enrolment DC | L38: 602375 | M38: DC | N38: 15 | P38: SecureShare Beacon H | Q38: DC | R38: 1 | S38: Auto Enrolment DC | T38: DC | U38: 45939.358 | V38: 45944.958 | W38: 1 | X38: 3.158044 | Y38: Mercer (Ireland) Limited | Z38: 25282CBPR0325AE | AA38: Beacon Hospital | AB38: Completed | AC38: Employer: N/A :: Number of Members: N/A | AD38: INTERNAL | AE38: 1 | AO38: TM12 | AP38: N
A39: 011352M | B39: NEBAUTO | C39: Day 4 | D39: In Service | E39: C192 | F39: A300 | G39: C192 | H39: TRUE | I39: 45944.655 | J39: Auto Enrolment DC | L39: 602903 | M39: DC | P39: SecureShare Brown Th | Q39: DC | R39: 1 | S39: Auto Enrolment DC | T39: DC | U39: 45939.378 | V39: 45944.958 | W39: 1 | X39: 3.2767824 | Y39: ILFS Corporate Business | Z39: 25282CBPR03266C | AA39: Brown Thomas Arnotts Limited | AB39: Completed | AC39: Employer: Brown Thomas Arnotts :: Number of Members: 4 | AD39: INTERNAL | AE39: 1 | AO39: TM05 | AP39: N
A40: 011355M | B40: NESAUTO | C40: Day 3 | D40: In Service | E40: F243 | F40: S168 | G40: F243 | H40: TRUE | I40: 45941.473 | J40: Auto Enrolment DC | K40: 1201699 | L40: 602944 | M40: DC | P40: SecureShare Patrick | Q40: DC | R40: 1 | S40: Auto Enrolment DC | T40: DC | U40: 45939.387 | V40: 45944.958 | W40: 1 | X40: 2.0867708 | Y40: Mercer (Elect Existing Business) | Z40: 25282CBPR03272C | AA40: PATRICK J TOBIN LTD | AB40: Completed | AC40: Saoirse Burke | AD40: INTERNAL | AE40: 1 | AO40: TM01 | AP40: N
...

Sheet SQL
A2: Select b.batch_id , b.batch_name, b.creation_date as Created, b.completed_date as Completed, b.num_data_records_loaded, b.num_data_records_valid, b.num_data_records_errored, b.num_data_records_skipped, b.created_by, b.attribute4 as Midas_No, b.status From SLDBA.BATCH b Where b.creation_date >= '06-01-2025' AND b.completed_date is not Null

Sheet Notes
A1: Objective
A2: Identify the secure share submissions and number of members loaded
A3: Ideally there is one Secure Share Submission with a unique Reference Number. This data is contained within the tab IP_ORG_Usecase_Submission_Statu
A4: That Reference Number number is then used as part of the bulk upload process. The Tab "Export Spreadsheet" contains the list up uploads. The Reference number is called MIDAS_NO on this tab
A5: By matching the Reference Number submission and upload we can tell how many members were added by using the NUM_DATA_RECORDS_LOADED column
A6: On top of wanting to know how many members were loaded I want to be able to drill down by "Organization Name" too
A14: Complication
A15: There may be more than 1 upload to PPI- this is because some members will fail. So a portion is loaded, Then another uploaded is done for the balance, but this also uses the same unique midas number
A16: If we take October as a reference there was only 2 such instances.
A19: IP_Org_Usecase_Submission_Statu
A20: Use Case Name | B20: Only Add members in scope
A21: Submission Status | B21: Only completed in scope
A22: I then do a look up of the Midas completed workitems (see Tableau single and bulk) to determine if it was single or bulk update
A23: I also do a check to determine the number of members loaded via PPI by checking the midas number v the Export Sheet (sharpload data)
A25: IP_Org_Usecase_Submission_Statu
A26: COMPLETED | B26: Not in date order so I ordered it
B27: I deleted everything pre 1st Oct | C27: I done this as submission data was only for Oct
A29: Tableau Single & Bulk
A30: This is just a downloaded of New Entrant Single and Bulk Workitems completed on Midas
